Workbook

Sheet Performance_Data
A1: Record ID | B1: Date | C1: Month | D1: Employee ID | E1: Employee Name | F1: Department | G1: Team | H1: Location | I1: Target Tasks | J1: Completed Tasks | K1: Quality Score | L1: Attendance Rate | M1: Customer Satisfaction | N1: Revenue (AED) | O1: Performance Score
A2: REC-0001 | B2: 45292 | C2: =DATE(YEAR(B2),MONTH(B2),1) -> 45292 | D2: EMP001 | E2: Ahmed Hassan | F2: Sales | G2: Enterprise Sales | H2: Dubai | I2: 38 | J2: 42 | K2: 0.93172764 | L2: 0.98951231 | M2: 0.9613605 | N2: 26850 | O2: =MIN(J2/I2,1.2)*40%+K2*25%+L2*15%+M2*20% -> 1.0157361
A3: REC-0002 | B3: 45293 | C3: =DATE(YEAR(B3),MONTH(B3),1) -> 45292 | D3: EMP002 | E3: Sara Ali | F3: Sales | G3: Enterprise Sales | H3: Abu Dhabi | I3: 55 | J3: 51 | K3: 0.90232729 | L3: 0.95194407 | M3: 0.91905392 | N3: 26660 | O3: =MIN(J3/I3,1.2)*40%+K3*25%+L3*15%+M3*20% -> 0.92309331
A4: REC-0003 | B4: 45293 | C4: =DATE(YEAR(B4),MONTH(B4),1) -> 45292 | D4: EMP003 | E4: Omar Khaled | F4: Operations | G4: Service Delivery | H4: Dubai | I4: 52 | J4: 44 | K4: 0.85940765 | L4: 0.94879677 | M4: 0.87747923 | N4: 17610 | O4: =MIN(J4/I4,1.2)*40%+K4*25%+L4*15%+M4*20% -> 0.87112881
A5: REC-0004 | B5: 45295 | C5: =DATE(YEAR(B5),MONTH(B5),1) -> 45292 | D5: EMP001 | E5: Ahmed Hassan | F5: Sales | G5: Enterprise Sales | H5: Dubai | I5: 51 | J5: 56 | K5: 0.92626726 | L5: 0.95870708 | M5: 0.92993762 | N5: 35720 | O5: =MIN(J5/I5,1.2)*40%+K5*25%+L5*15%+M5*20% -> 1.0005761
A6: REC-0005 | B6: 45296 | C6: =DATE(YEAR(B6),MONTH(B6),1) -> 45292 | D6: EMP001 | E6: Ahmed Hassan | F6: Sales | G6: Enterprise Sales | H6: Dubai | I6: 47 | J6: 51 | K6: 0.92763621 | L6: 0.95265104 | M6: 0.91374479 | N6: 28620 | O6: =MIN(J6/I6,1.2)*40%+K6*25%+L6*15%+M6*20% -> 0.99159822
A7: REC-0006 | B7: 45296 | C7: =DATE(YEAR(B7),MONTH(B7),1) -> 45292 | D7: EMP002 | E7: Sara Ali | F7: Sales | G7: Enterprise Sales | H7: Abu Dhabi | I7: 28 | J7: 28 | K7: 0.92977855 | L7: 0.93824673 | M7: 0.90403077 | N7: 15180 | O7: =MIN(J7/I7,1.2)*40%+K7*25%+L7*15%+M7*20% -> 0.9539878
A8: REC-0007 | B8: 45300 | C8: =DATE(YEAR(B8),MONTH(B8),1) -> 45292 | D8: EMP005 | E8: Youssef Ibrahim | F8: Customer Experience | G8: Customer Success | H8: Dubai | I8: 55 | J8: 55 | K8: 0.93842346 | L8: 0.95844009 | M8: 0.96565996 | N8: 24780 | O8: =MIN(J8/I8,1.2)*40%+K8*25%+L8*15%+M8*20% -> 0.97150387
A9: REC-0008 | B9: 45301 | C9: =DATE(YEAR(B9),MONTH(B9),1) -> 45292 | D9: EMP006 | E9: Nour Mohamed | F9: Customer Experience | G9: Customer Success | H9: Abu Dhabi | I9: 55 | J9: 63 | K9: 0.98761873 | L9: 0.96188982 | M9: 0.995 | N9: 34320 | O9: =MIN(J9/I9,1.2)*40%+K9*25%+L9*15%+M9*20% -> 1.04837
A10: REC-0009 | B10: 45302 | C10: =DATE(YEAR(B10),MONTH(B10),1) -> 45292 | D10: EMP005 | E10: Youssef Ibrahim | F10: Customer Experience | G10: Customer Success | H10: Dubai | I10: 31 | J10: 30 | K10: 0.95989637 | L10: 0.93643893 | M10: 0.93580629 | N10: 14190 | O10: =MIN(J10/I10,1.2)*40%+K10*25%+L10*15%+M10*20% -> 0.95469796
A11: REC-0010 | B11: 45303 | C11: =DATE(YEAR(B11),MONTH(B11),1) -> 45292 | D11: EMP004 | E11: Mariam Adel | F11: Operations | G11: Service Delivery | H11: Sharjah | I11: 48 | J11: 53 | K11: 0.93816487 | L11: 0.95932481 | M11: 0.92605973 | N11: 20350 | O11: =MIN(J11/I11,1.2)*40%+K11*25%+L11*15%+M11*20% -> 1.0053186
A12: REC-0011 | B12: 45303 | C12: =DATE(YEAR(B12),MONTH(B12),1) -> 45292 | D12: EMP004 | E12: Mariam Adel | F12: Operations | G12: Service Delivery | H12: Sharjah | I12: 37 | J12: 40 | K12: 0.93800889 | L12: 0.96002558 | M12: 0.85786199 | N12: 17680 | O12: =MIN(J12/I12,1.2)*40%+K12*25%+L12*15%+M12*20% -> 0.98251089
A13: REC-0012 | B13: 45303 | C13: =DATE(YEAR(B13),MONTH(B13),1) -> 45292 | D13: EMP005 | E13: Youssef Ibrahim | F13: Customer Experience | G13: Customer Success | H13: Dubai | I13: 46 | J13: 43 | K13: 0.95793119 | L13: 0.93479791 | M13: 0.995 | N13: 18620 | O13: =MIN(J13/I13,1.2)*40%+K13*25%+L13*15%+M13*20% -> 0.95261553
... A1001: REC-1000 | B1001: 46265 | C1001: =DATE(YEAR(B1001),MONTH(B1001),1) -> 46235 | D1001: EMP005 | E1001: Youssef Ibrahim | F1001: Customer Experience | G1001: Customer Success | H1001: Dubai | I1001: 30 | J1001: 27 | K1001: 0.90369546 | L1001: 0.95900623 | M1001: 0.942111 | N1001: 11560 | O1001: =MIN(J1001/I1001,1.2)*40%+K1001*25%+L1001*15%+M1001*20% -> 0.918197

Sheet Dashbourd
O2: =IFERROR((BA11-BA12)/BA12,"")
C5: Month | H5: Employee Name | M5: Department | R5: Team | W5: Location
C6: 45566 | H6: All | M6: Operations | R6: All | W6: All
AQ9: =IFERROR((AO11-AO12)/AO12,"") -> 0.2240204
AU10: =AVERAGEIFS(Performance_Data!O:O, Performance_Data!C:C,IF(Dashbourd!$C$6="All","<>",Dashbourd!$C$6), Performance_Data!E:E,IF(Dashbourd!$H$6="All","<>",Dashbourd!$H$6), Performance_Data!F:F,IF(Dashbourd!$M$6="All","<>",Dashbourd!$M$6), Performance_Data!G:G,IF(Dashbourd!$R$6="All","<>",Dashbourd!$R$6), Performance_Data!H:H,IF(Dashbourd!$W$6="All","<>",Dashbourd!$W$6)) -> 0.9356323 | AZ10: =AVERAGEIFS(Performance_Data!L:L, Performance_Data!C:C,IF(Dashbourd!$C$6="All","<>",Dashbourd!$C$6), Performance_Data!E:E,IF(Dashbourd!$H$6="All","<>",Dashbourd!$H$6), Performance_Data!F:F,IF(Dashbourd!$M$6="All","<>",Dashbourd!$M$6), Performance_Data!G:G,IF(Dashbourd!$R$6="All","<>",Dashbourd!$R$6), Performance_Data!H:H,IF(Dashbourd!$W$6="All","<>",Dashbourd!$W$6)) -> 0.95372764 | BE10: =AVERAGEIFS(Performance_Data!K:K, Performance_Data!C:C,IF(Dashbourd!$C$6="All","<>",Dashbourd!$C$6), Performance_Data!E:E,IF(Dashbourd!$H$6="All","<>",Dashbourd!$H$6), Performance_Data!F:F,IF(Dashbourd!$M$6="All","<>",Dashbourd!$M$6), Performance_Data!G:G,IF(Dashbourd!$R$6="All","<>",Dashbourd!$R$6), Performance_Data!H:H,IF(Dashbourd!$W$6="All","<>",Dashbourd!$W$6)) -> 0.91879919 | BJ10: =AVERAGEIFS(Performance_Data!M:M, Performance_Data!C:C,IF(Dashbourd!$C$6="All","<>",Dashbourd!$C$6), Performance_Data!E:E,IF(Dashbourd!$H$6="All","<>",Dashbourd!$H$6), Performance_Data!F:F,IF(Dashbourd!$M$6="All","<>",Dashbourd!$M$6), Performance_Data!G:G,IF(Dashbourd!$R$6="All","<>",Dashbourd!$R$6), Performance_Data!H:H,IF(Dashbourd!$W$6="All","<>",Dashbourd!$W$6)) -> 0.90640578 | BO10: =AVERAGEIFS(Performance_Data!I:I, Performance_Data!C:C,IF(Dashbourd!$C$6="All","<>",Dashbourd!$C$6), Performance_Data!E:E,IF(Dashbourd!$H$6="All","<>",Dashbourd!$H$6), Performance_Data!F:F,IF(Dashbourd!$M$6="All","<>",Dashbourd!$M$6), Performance_Data!G:G,IF(Dashbourd!$R$6="All","<>",Dashbourd!$R$6), Performance_Data!H:H,IF(Dashbourd!$W$6="All","<>",Dashbourd!$W$6)) -> 42.428571
AO11: =SUMIFS(Performance_Data!N:N, Performance_Data!C:C,IF(Dashbourd!$C$6="All","<>",Dashbourd!$C$6), Performance_Data!E:E,IF(Dashbourd!$H$6="All","<>",Dashbourd!$H$6), Performance_Data!F:F,IF(Dashbourd!$M$6="All","<>",Dashbourd!$M$6), Performance_Data!G:G,IF(Dashbourd!$R$6="All","<>",Dashbourd!$R$6), Performance_Data!H:H,IF(Dashbourd!$W$6="All","<>",Dashbourd!$W$6)) -> 235220 | AP11: =IFERROR(($AO$11-$AO$12)/$AO$12,"") -> 0.2240204 | AQ11: =IFERROR(($AO$11-$AO$12)/$AO$12,"") -> 0.2240204 | AU11: =AVERAGEIFS(Performance_Data!O:O, Performance_Data!C:C,EDATE($C$6,-1), Performance_Data!E:E,IF(Dashbourd!$H$6="All","<>",Dashbourd!$H$6), Performance_Data!F:F,IF(Dashbourd!$M$6="All","<>",Dashbourd!$M$6), Performance_Data!G:G,IF(Dashbourd!$R$6="All","<>",Dashbourd!$R$6), Performance_Data!H:H,IF(Dashbourd!$W$6="All","<>",Dashbourd!$W$6)) -> 0.92683866 | AV11: =IFERROR((AU10-AU11)/AU11,"") -> 0.0094877767 | AZ11: =AVERAGEIFS(Performance_Data!L:L, Performance_Data!C:C,EDATE($C$6,-1), Performance_Data!E:E,IF(Dashbourd!$H$6="All","<>",Dashbourd!$H$6), Performance_Data!F:F,IF(Dashbourd!$M$6="All","<>",Dashbourd!$M$6), Performance_Data!G:G,IF(Dashbourd!$R$6="All","<>",Dashbourd!$R$6), Performance_Data!H:H,IF(Dashbourd!$W$6="All","<>",Dashbourd!$W$6)) -> 0.95087209 | BA11: =IFERROR((AZ10-AZ11)/AZ11,"") -> 0.0030030817 | BE11: =AVERAGEIFS(Performance_Data!K:K, Performance_Data!C:C,EDATE($C$6,-1), Performance_Data!E:E,IF(Dashbourd!$H$6="All","<>",Dashbourd!$H$6), Performance_Data!F:F,IF(Dashbourd!$M$6="All","<>",Dashbourd!$M$6), Performance_Data!G:G,IF(Dashbourd!$R$6="All","<>",Dashbourd!$R$6), Performance_Data!H:H,IF(Dashbourd!$W$6="All","<>",Dashbourd!$W$6)) -> 0.91942815 | BF11: =IFERROR((BE10-BE11)/BE11,"") -> -0.00068407 | BJ11: =AVERAGEIFS(Performance_Data!M:M, Performance_Data!C:C,EDATE($C$6,-1), Performance_Data!E:E,IF(Dashbourd!$H$6="All","<>",Dashbourd!$H$6), Performance_Data!F:F,IF(Dashbourd!$M$6="All","<>",Dashbourd!$M$6), Performance_Data!G:G,IF(Dashbourd!$R$6="All","<>",Dashbourd!$R$6), Performance_Data!H:H,IF(Dashbourd!$W$6="All","<>",Dashbourd!$W$6)) -> 0.90263064 | BK11: =IFERROR((BJ10-BJ11)/BJ11,"") -> 0.0041823783 | BO11: =AVERAGEIFS(Performance_Data!J:J, Performance_Data!C:C,IF(Dashbourd!$C$6="All","<>",Dashbourd!$C$6), Performance_Data!E:E,IF(Dashbourd!$H$6="All","<>",Dashbourd!$H$6), Performance_Data!F:F,IF(Dashbourd!$M$6="All","<>",Dashbourd!$M$6), Performance_Data!G:G,IF(Dashbourd!$R$6="All","<>",Dashbourd!$R$6), Performance_Data!H:H,IF(Dashbourd!$W$6="All","<>",Dashbourd!$W$6)) -> 40.642857 | BP11: =IFERROR((BO10-BO11)/BO11,"") -> 0.043936731
AO12: =SUMIFS(Performance_Data!N:N, Performance_Data!C:C,EDATE(Dashbourd!$C$6,-1), Performance_Data!E:E,IF(Dashbourd!$H$6="All","<>",Dashbourd!$H$6), Performance_Data!F:F,IF(Dashbourd!$M$6="All","<>",Dashbourd!$M$6), Performance_Data!G:G,IF(Dashbourd!$R$6="All","<>",Dashbourd!$R$6), Performance_Data!H:H,IF(Dashbourd!$W$6="All","<>",Dashbourd!$W$6)) -> 192170
AO13: =SUMIFS(Performance_Data!N:N, Performance_Data!C:C,EDATE(Dashbourd!$C$6,-2), Performance_Data!E:E,IF(Dashbourd!$H$6="All","<>",Dashbourd!$H$6), Performance_Data!F:F,IF(Dashbourd!$M$6="All","<>",Dashbourd!$M$6), Performance_Data!G:G,IF(Dashbourd!$R$6="All","<>",Dashbourd!$R$6), Performance_Data!H:H,IF(Dashbourd!$W$6="All","<>",Dashbourd!$W$6)) -> 166970
AO14: =SUMIFS(Performance_Data!N:N, Performance_Data!C:C,EDATE(Dashbourd!$C$6,-3), Performance_Data!E:E,IF(Dashbourd!$H$6="All","<>",Dashbourd!$H$6), Performance_Data!F:F,IF(Dashbourd!$M$6="All","<>",Dashbourd!$M$6), Performance_Data!G:G,IF(Dashbourd!$R$6="All","<>",Dashbourd!$R$6), Performance_Data!H:H,IF(Dashbourd!$W$6="All","<>",Dashbourd!$W$6)) -> 182810
AO15: =SUMIFS(Performance_Data!N:N, Performance_Data!C:C,EDATE(Dashbourd!$C$6,-4), Performance_Data!E:E,IF(Dashbourd!$H$6="All","<>",Dashbourd!$H$6), Performance_Data!F:F,IF(Dashbourd!$M$6="All","<>",Dashbourd!$M$6), Performance_Data!G:G,IF(Dashbourd!$R$6="All","<>",Dashbourd!$R$6), Performance_Data!H:H,IF(Dashbourd!$W$6="All","<>",Dashbourd!$W$6)) -> 114830
E22: =IFERROR((C22-D24)/D24,"") | J22: =IFERROR((H22-H23)/H23,"")

Sheet Calculations
B2: Month | C2: Employee Name | D2: Department | E2: Team | F2: Location
B3: All | C3: All | D3: All | E3: All | F3: All
B4: {=_xlfn.UNIQUE(table[Month],FALSE,FALSE)} -> 45292 | C4: {=_xlfn.UNIQUE(table[Employee Name],FALSE,FALSE)} -> Ahmed Hassan | D4: {=_xlfn.UNIQUE(table[Department],FALSE,FALSE)} -> Sales | E4: {=_xlfn.UNIQUE(table[Team],FALSE,FALSE)} -> Enterprise Sales | F4: {=_xlfn.UNIQUE(table[Location],FALSE,FALSE)} -> Dubai
B5: 45323 | C5: Sara Ali | D5: Operations | E5: Service Delivery | F5: Abu Dhabi
B6: 45352 | C6: Omar Khaled | D6: Customer Experience | E6: Customer Success | F6: Sharjah
B7: 45383 | C7: Youssef Ibrahim
B8: 45413 | C8: Nour Mohamed | AM8: Row Labels | AN8: Sum of Revenue (AED)
B9: 45444 | C9: Mariam Adel | K9: Row Labels | L9: Sum of Revenue (AED) | AM9: Abu Dhabi | AN9: 7507860
B10: 45474 | K10: 2024 | L10: 7503550 | AM10: Dubai | AN10: 10094210 | AY10: Location | AZ10: (All)
B11: 45505 | K11: Jan | L11: 559290 | W11: Row Labels | X11: Average of Performance Score | AM11: Sharjah | AN11: 3047800 | AY11: Month | AZ11: (All)
B12: 45536 | K12: Feb | L12: 676330 | W12: Nour Mohamed | X12: 1.0151623 | AM12: Grand Total | AN12: 20649870 | AY12: Team | AZ12: (All)
B13: 45566 | K13: Mar | L13: 602060 | W13: Ahmed Hassan | X13: 0.99739132 | AF13: Row Labels | AG13: Sum of Revenue (AED) | AY13: Department | AZ13: (All)
B14: 45597 | K14: Apr | L14: 814760 | W14: Mariam Adel | X14: 0.98379307 | AF14: Customer Experience | AG14: 6701760
B15: 45627 | K15: May | L15: 853160 | W15: Sara Ali | X15: 0.96370163 | AF15: Operations | AG15: 5672850 | AY15: Row Labels | AZ15: Average of Performance Score
B16: 45658 | K16: Jun | L16: 494850 | W16: Youssef Ibrahim | X16: 0.95848739 | AF16: Sales | AG16: 8275260 | AY16: Ahmed Hassan | AZ16: 0.99739132
B17: 45689 | K17: Jul | L17: 618340 | W17: Omar Khaled | X17: 0.92708588 | AF17: Grand Total | AG17: 20649870 | AY17: Mariam Adel | AZ17: 0.98379307
B18: 45717 | K18: Aug | L18: 551640 | W18: Grand Total | X18: 0.97424515 | AY18: Nour Mohamed | AZ18: 1.0151623
B19: 45748 | K19: Sep | L19: 615780 | AY19: Omar Khaled | AZ19: 0.92708588
B20: 45778 | K20: Oct | L20: 680350 | AY20: Sara Ali | AZ20: 0.96370163
B21: 45809 | K21: Nov | L21: 602040 | AY21: Youssef Ibrahim | AZ21: 0.95848739
B22: 45839 | K22: Dec | L22: 434950 | AY22: Grand Total | AZ22: 0.97424515
B23: 45870 | K23: 2025 | L23: 8467110
B24: 45901 | K24: Jan | L24: 731640
B25: 45931 | K25: Feb | L25: 754780
B26: 45962 | K26: Mar | L26: 724900
B27: 45992 | K27: Apr | L27: 815090
B28: 46023 | K28: May | L28: 713690
B29: 46054 | K29: Jun | L29: 544910
B30: 46082 | K30: Jul | L30: 702320
B31: 46113 | K31: Aug | L31: 701010
B32: 46143 | K32: Sep | L32: 604660
B33: 46174 | K33: Oct | L33: 1017760
B34: 46204 | K34: Nov | L34: 569770
B35: 46235 | K35: Dec | L35: 586580
K36: 2026 | L36: 4679210
K37: Jan | L37: 639750
K38: Feb | L38: 702330
K39: Mar | L39: 631570
K40: Apr | L40: 476570
K41: May | L41: 557230
...

Sheet Data_Dictionary
A1: Column | B1: Description | C1: Dashboard Use
A2: Record ID | B2: Unique identifier for each performance record. | C2: Count of records / drill-through.
A3: Date | B3: Date of the activity/performance record. | C3: Daily trend, timeline filters.
A4: Month | B4: First day of the month derived from Date. | C4: Monthly trend, slicers, Pivot grouping.
A5: Employee ID | B5: Unique employee code. | C5: Employee-level filtering.
A6: Employee Name | B6: Name of one of the six employees. | C6: Ranking, comparison, slicers.
A7: Department | B7: Business department: Sales, Operations, or Customer Experience. | C7: Department comparison.
A8: Team | B8: Team within the department. | C8: Team-level performance comparison.
A9: Location | B9: Primary work location. | C9: Geographic / location slicing.
A10: Target Tasks | B10: Expected number of tasks for the record. | C10: Target KPI.
A11: Completed Tasks | B11: Actual completed tasks. | C11: Actual KPI and productivity.
A12: Quality Score | B12: Quality assessment as a percentage. | C12: Quality KPI.
... A16: Performance Score | B16: Weighted score: 40% productivity, 25% quality, 15% attendance, 20% CSAT. | C16: Overall performance KPI / ranking.
A18: Performance Score = MIN(Completed Tasks ÷ Target Tasks, 120%) × 40% + Quality × 25% + Attendance × 15% + CSAT × 20%
